<?xml version="1.0" encoding="utf-8"?>
<!-- This URDF was automatically created by SolidWorks to URDF Exporter! Originally created by Stephen Brawner (brawner@gmail.com) 
     Commit Version: 1.6.0-1-g15f4949  Build Version: 1.6.7594.29634
     For more information, please see http://wiki.ros.org/sw_urdf_exporter -->
<robot
  name="hexaurdf10">
  <link
    name="base_link">
    <inertial>
      <origin
        xyz="-9.01995993685678E-05 -7.02233808926034E-06 -0.0170204486555059"
        rpy="0 0 0" />
      <mass
        value="0.427164873283659" />
      <inertia
        ixx="0.000389419100678071"
        ixy="-2.19452864339234E-08"
        ixz="2.42560577867763E-09"
        iyy="0.000935141379406109"
        iyz="2.11587249040115E-08"
        izz="0.00122689626017959" />
    </inertial>
    <visual>
      <origin
        xyz="0 0 0"
        rpy="0 0 0" />
      <geometry>
        <mesh
          filename="package://hexaurdf10/meshes/base_link.STL" />
      </geometry>
      <material
        name="">
        <color
          rgba="0.792156862745098 0.819607843137255 0.933333333333333 1" />
      </material>
    </visual>
    <collision>
      <origin
        xyz="0 0 0"
        rpy="0 0 0" />
      <geometry>
        <mesh
          filename="package://hexaurdf10/meshes/base_link.STL" />
      </geometry>
    </collision>
  </link>
  <link
    name="coxa1">
    <inertial>
      <origin
        xyz="-0.00996677615501421 0.0534816504142664 0.0283131774124853"
        rpy="0 0 0" />
      <mass
        value="0.115130491493586" />
      <inertia
        ixx="8.27245013930469E-05"
        ixy="1.1604100599582E-05"
        ixz="4.29413505869315E-08"
        iyy="4.24173396939557E-05"
        iyz="-1.89820233719475E-07"
        izz="7.59549025648864E-05" />
    </inertial>
    <visual>
      <origin
        xyz="0 0 0"
        rpy="0 0 0" />
      <geometry>
        <mesh
          filename="package://hexaurdf10/meshes/coxa1.STL" />
      </geometry>
      <material
        name="">
        <color
          rgba="0.792156862745098 0.819607843137255 0.933333333333333 1" />
      </material>
    </visual>
    <collision>
      <origin
        xyz="0 0 0"
        rpy="0 0 0" />
      <geometry>
        <mesh
          filename="package://hexaurdf10/meshes/coxa1.STL" />
      </geometry>
    </collision>
  </link>
  <joint
    name="coxajt1"
    type="revolute">
    <origin
      xyz="-0.087434 0.047179 -0.05093"
      rpy="0 0 0" />
    <parent
      link="base_link" />
    <child
      link="coxa1" />
    <axis
      xyz="0 0 -1" />
    <limit
      lower="-1.57"
      upper="1.57"
      effort="100"
      velocity="100" />
  </joint>
  <link
    name="femur1">
    <inertial>
      <origin
        xyz="-0.0392463982034434 0.033810727811229 0.0314749457890496"
        rpy="0 0 0" />
      <mass
        value="0.0660859499924982" />
      <inertia
        ixx="5.32337357848377E-05"
        ixy="-4.48717442269826E-07"
        ixz="5.18265128385917E-06"
        iyy="5.50193485031449E-05"
        iyz="-2.18528856203791E-05"
        izz="6.82136138765561E-05" />
    </inertial>
    <visual>
      <origin
        xyz="0 0 0"
        rpy="0 0 0" />
      <geometry>
        <mesh
          filename="package://hexaurdf10/meshes/femur1.STL" />
      </geometry>
      <material
        name="">
        <color
          rgba="0.792156862745098 0.819607843137255 0.933333333333333 1" />
      </material>
    </visual>
    <collision>
      <origin
        xyz="0 0 0"
        rpy="0 0 0" />
      <geometry>
        <mesh
          filename="package://hexaurdf10/meshes/femur1.STL" />
      </geometry>
    </collision>
  </link>
  <joint
    name="femurjt1"
    type="revolute">
    <origin
      xyz="0.016657 0.085859 0.0282"
      rpy="0 0 0" />
    <parent
      link="coxa1" />
    <child
      link="femur1" />
    <axis
      xyz="0.97301 0.23076 0" />
    <limit
      lower="-1.57"
      upper="1.57"
      effort="100"
      velocity="100" />
  </joint>
  <link
    name="tibia1">
    <inertial>
      <origin
        xyz="-0.0309143702456073 -0.00434467341630906 -0.0239746701916343"
        rpy="0 0 0" />
      <mass
        value="0.0831637264780428" />
      <inertia
        ixx="7.26680960269865E-05"
        ixy="-7.47150261741655E-07"
        ixz="-5.40895617606461E-07"
        iyy="7.49625351804961E-05"
        iyz="7.60546051470148E-06"
        izz="1.5460696027227E-05" />
    </inertial>
    <visual>
      <origin
        xyz="0 0 0"
        rpy="0 0 0" />
      <geometry>
        <mesh
          filename="package://hexaurdf10/meshes/tibia1.STL" />
      </geometry>
      <material
        name="">
        <color
          rgba="0.792156862745098 0.819607843137255 0.933333333333333 1" />
      </material>
    </visual>
    <collision>
      <origin
        xyz="0 0 0"
        rpy="0 0 0" />
      <geometry>
        <mesh
          filename="package://hexaurdf10/meshes/tibia1.STL" />
      </geometry>
    </collision>
  </link>
  <joint
    name="tibiajt1"
    type="revolute">
    <origin
      xyz="-0.0205222673024253 0.0756993537012256 0.0588106656482051"
      rpy="0 0 0" />
    <parent
      link="femur1" />
    <child
      link="tibia1" />
    <axis
      xyz="0.973010691759489 0.23076003493179 0" />
    <limit
      lower="-1.57"
      upper="1.57"
      effort="100"
      velocity="100" />
  </joint>
  <link
    name="tip1">
    <inertial>
      <origin
        xyz="2.8944120935015E-05 -0.000122044266207932 0.0010109650611296"
        rpy="0 0 0" />
      <mass
        value="0.000239235376940892" />
      <inertia
        ixx="1.17700421937413E-09"
        ixy="-2.38032850442416E-10"
        ixz="1.72208787878232E-11"
        iyy="2.12422901332552E-09"
        iyz="-7.26126566370207E-11"
        izz="2.7729159203194E-09" />
    </inertial>
    <visual>
      <origin
        xyz="0 0 0"
        rpy="0 0 0" />
      <geometry>
        <mesh
          filename="package://hexaurdf10/meshes/tip1.STL" />
      </geometry>
      <material
        name="">
        <color
          rgba="0.792156862745098 0.819607843137255 0.933333333333333 1" />
      </material>
    </visual>
    <collision>
      <origin
        xyz="0 0 0"
        rpy="0 0 0" />
      <geometry>
        <mesh
          filename="package://hexaurdf10/meshes/tip1.STL" />
      </geometry>
    </collision>
  </link>
  <joint
    name="tip1_jt"
    type="fixed">
    <origin
      xyz="-0.036037 0.0066924 -0.1204"
      rpy="0 0 0" />
    <parent
      link="tibia1" />
    <child
      link="tip1" />
    <axis
      xyz="0 0 0" />
    <limit
      effort="100"
      velocity="100" />
  </joint>
  <link
    name="coxa2">
    <inertial>
      <origin
        xyz="0.00702595295081485 0.0539468244177731 0.0283131778377294"
        rpy="0 0 0" />
      <mass
        value="0.115130507631966" />
      <inertia
        ixx="8.56982209412201E-05"
        ixy="-2.43935388135997E-06"
        ixz="-1.77400455222318E-08"
        iyy="3.94436340830869E-05"
        iyz="-1.9380729963882E-07"
        izz="7.59549161277092E-05" />
    </inertial>
    <visual>
      <origin
        xyz="0 0 0"
        rpy="0 0 0" />
      <geometry>
        <mesh
          filename="package://hexaurdf10/meshes/coxa2.STL" />
      </geometry>
      <material
        name="">
        <color
          rgba="0.792156862745098 0.819607843137255 0.933333333333333 1" />
      </material>
    </visual>
    <collision>
      <origin
        xyz="0 0 0"
        rpy="0 0 0" />
      <geometry>
        <mesh
          filename="package://hexaurdf10/meshes/coxa2.STL" />
      </geometry>
    </collision>
  </link>
  <joint
    name="coxajt2"
    type="revolute">
    <origin
      xyz="1.04119442682904E-05 0.0419777704086039 -0.05093"
      rpy="0 0 0" />
    <parent
      link="base_link" />
    <child
      link="coxa2" />
    <axis
      xyz="0 0 -1" />
    <limit
      lower="-1.57"
      upper="1.57"
      effort="100"
      velocity="100" />
  </joint>
  <link
    name="femur2">
    <inertial>
      <origin
        xyz="-0.026895361536933 0.0442728429591131 0.0314749456998863"
        rpy="0 0 0" />
      <mass
        value="0.0660859497825229" />
      <inertia
        ixx="5.31403664096481E-05"
        ixy="1.60960814885035E-07"
        ixz="-1.81486478003954E-06"
        iyy="5.51127174166766E-05"
        iyz="-2.23855924043355E-05"
        izz="6.82136133643609E-05" />
    </inertial>
    <visual>
      <origin
        xyz="0 0 0"
        rpy="0 0 0" />
      <geometry>
        <mesh
          filename="package://hexaurdf10/meshes/femur2.STL" />
      </geometry>
      <material
        name="">
        <color
          rgba="0.792156862745098 0.819607843137255 0.933333333333333 1" />
      </material>
    </visual>
    <collision>
      <origin
        xyz="0 0 0"
        rpy="0 0 0" />
      <geometry>
        <mesh
          filename="package://hexaurdf10/meshes/femur2.STL" />
      </geometry>
    </collision>
  </link>
  <joint
    name="femurjt2"
    type="revolute">
    <origin
      xyz="0.0423424111674541 0.0765264348093442 0.0282"
      rpy="0 0 0" />
    <parent
      link="coxa2" />
    <child
      link="femur2" />
    <axis
      xyz="0.996729696182891 -0.080807875526849 0" />
    <limit
      lower="-1.57"
      upper="1.57"
      effort="100"
      velocity="100" />
  </joint>
  <link
    name="tibia2">
    <inertial>
      <origin
        xyz="-0.0307460867657561 0.00540861064554149 -0.0239746471855047"
        rpy="0 0 0" />
      <mass
        value="0.0831636657575238" />
      <inertia
        ixx="7.24479308066596E-05"
        ixy="6.87431336759013E-08"
        ixz="1.83278628407196E-06"
        iyy="7.51826173621094E-05"
        iyz="7.40113031131103E-06"
        izz="1.54606798866916E-05" />
    </inertial>
    <visual>
      <origin
        xyz="0 0 0"
        rpy="0 0 0" />
      <geometry>
        <mesh
          filename="package://hexaurdf10/meshes/tibia2.STL" />
      </geometry>
      <material
        name="">
        <color
          rgba="0.792156862745098 0.819607843137255 0.933333333333333 1" />
      </material>
    </visual>
    <collision>
      <origin
        xyz="0 0 0"
        rpy="0 0 0" />
      <geometry>
        <mesh
          filename="package://hexaurdf10/meshes/tibia2.STL" />
      </geometry>
    </collision>
  </link>
  <joint
    name="tibiajt2"
    type="revolute">
    <origin
      xyz="0.0038428667079584 0.0783376536633586 0.0588106656482051"
      rpy="0 0 0" />
    <parent
      link="femur2" />
    <child
      link="tibia2" />
    <axis
      xyz="0.996729696182889 -0.0808078755268694 0" />
    <limit
      lower="-1.57"
      upper="1.57"
      effort="100"
      velocity="100" />
  </joint>
  <link
    name="tip2">
    <inertial>
      <origin
        xyz="-1.01356932210722E-05 -0.000125019329600962 0.00101096506112963"
        rpy="0 0 0" />
      <mass
        value="0.000239235376940891" />
      <inertia
        ixx="1.12747469759534E-09"
        ixy="8.53866107810884E-11"
        ixz="-6.03043169915054E-12"
        iyy="2.1737585351043E-09"
        iyz="-7.43827296059554E-11"
        izz="2.77291592031939E-09" />
    </inertial>
    <visual>
      <origin
        xyz="0 0 0"
        rpy="0 0 0" />
      <geometry>
        <mesh
          filename="package://hexaurdf10/meshes/tip2.STL" />
      </geometry>
      <material
        name="">
        <color
          rgba="0.792156862745098 0.819607843137255 0.933333333333333 1" />
      </material>
    </visual>
    <collision>
      <origin
        xyz="0 0 0"
        rpy="0 0 0" />
      <geometry>
        <mesh
          filename="package://hexaurdf10/meshes/tip2.STL" />
      </geometry>
    </collision>
  </link>
  <joint
    name="tip2_jt"
    type="fixed">
    <origin
      xyz="-0.032212 0.017488 -0.1204"
      rpy="0 0 0" />
    <parent
      link="tibia2" />
    <child
      link="tip2" />
    <axis
      xyz="0 0 0" />
    <limit
      effort="100"
      velocity="100" />
  </joint>
  <link
    name="coxa3">
    <inertial>
      <origin
        xyz="0.0221997669125888 0.0542198822140822 0.0283131763965716"
        rpy="0 0 0" />
      <mass
        value="0.115130485576148" />
      <inertia
        ixx="8.22944716782395E-05"
        ixy="-1.23208399526327E-05"
        ixz="-6.08415393151183E-08"
        iyy="4.28473562555238E-05"
        iyz="-1.84857912109661E-07"
        izz="7.59548987313903E-05" />
    </inertial>
    <visual>
      <origin
        xyz="0 0 0"
        rpy="0 0 0" />
      <geometry>
        <mesh
          filename="package://hexaurdf10/meshes/coxa3.STL" />
      </geometry>
      <material
        name="">
        <color
          rgba="0.792156862745098 0.819607843137255 0.933333333333333 1" />
      </material>
    </visual>
    <collision>
      <origin
        xyz="0 0 0"
        rpy="0 0 0" />
      <geometry>
        <mesh
          filename="package://hexaurdf10/meshes/coxa3.STL" />
      </geometry>
    </collision>
  </link>
  <joint
    name="coxajt3"
    type="revolute">
    <origin
      xyz="0.0872345529340218 0.0471785774978925 -0.05093"
      rpy="0 0 0" />
    <parent
      link="base_link" />
    <child
      link="coxa3" />
    <axis
      xyz="0 0 -1" />
    <limit
      lower="-1.57"
      upper="1.57"
      effort="100"
      velocity="100" />
  </joint>
  <link
    name="femur3">
    <inertial>
      <origin
        xyz="-0.0162592743139039 0.0491841543475647 0.0314749458152822"
        rpy="0 0 0" />
      <mass
        value="0.0660859500921707" />
      <inertia
        ixx="5.33104419164701E-05"
        ixy="5.76568115017335E-07"
        ixz="-6.79858949034281E-06"
        iyy="5.49426426164688E-05"
        iyz="-2.14053186576423E-05"
        izz="6.82136141038596E-05" />
    </inertial>
    <visual>
      <origin
        xyz="0 0 0"
        rpy="0 0 0" />
      <geometry>
        <mesh
          filename="package://hexaurdf10/meshes/femur3.STL" />
      </geometry>
      <material
        name="">
        <color
          rgba="0.792156862745098 0.819607843137255 0.933333333333333 1" />
      </material>
    </visual>
    <collision>
      <origin
        xyz="0 0 0"
        rpy="0 0 0" />
      <geometry>
        <mesh
          filename="package://hexaurdf10/meshes/femur3.STL" />
      </geometry>
    </collision>
  </link>
  <joint
    name="femurjt3"
    type="revolute">
    <origin
      xyz="0.0616868050052167 0.0682863147581348 0.0282000000000001"
      rpy="0 0 0" />
    <parent
      link="coxa3" />
    <child
      link="femur3" />
    <axis
      xyz="0.956610607760163 -0.291369430655879 0" />
    <limit
      lower="-1.57"
      upper="1.57"
      effort="100"
      velocity="100" />
  </joint>
  <link
    name="tibia3">
    <inertial>
      <origin
        xyz="-0.0287444949835653 0.0121790653958599 -0.0239746721026053"
        rpy="0 0 0" />
      <mass
        value="0.0831637267082012" />
      <inertia
        ixx="7.26161503309913E-05"
        ixy="6.60572388016064E-07"
        ixz="3.44896050681693E-06"
        iyy="7.50144818707885E-05"
        iyz="6.80001578776771E-06"
        izz="1.54606943376897E-05" />
    </inertial>
    <visual>
      <origin
        xyz="0 0 0"
        rpy="0 0 0" />
      <geometry>
        <mesh
          filename="package://hexaurdf10/meshes/tibia3.STL" />
      </geometry>
      <material
        name="">
        <color
          rgba="0.792156862745098 0.819607843137255 0.933333333333333 1" />
      </material>
    </visual>
    <collision>
      <origin
        xyz="0 0 0"
        rpy="0 0 0" />
      <geometry>
        <mesh
          filename="package://hexaurdf10/meshes/tibia3.STL" />
      </geometry>
    </collision>
  </link>
  <joint
    name="tibiajt3"
    type="revolute">
    <origin
      xyz="0.0213473915477253 0.0754708187322992 0.0588106656482051"
      rpy="0 0 0" />
    <parent
      link="femur3" />
    <child
      link="tibia3" />
    <axis
      xyz="0.956610607760165 -0.291369430655872 0" />
    <limit
      lower="-1.57"
      upper="1.57"
      effort="100"
      velocity="100" />
  </joint>
  <link
    name="tip3">
    <inertial>
      <origin
        xyz="0.00101096506112963 -0.000119544680993067 3.79688595718852E-05"
        rpy="0 0 0" />
      <mass
        value="0.000239235376940891" />
      <inertia
        ixx="2.77291592031939E-09"
        ixy="-7.11254788401556E-11"
        ixz="2.25903260239757E-11"
        iyy="2.0835374700736E-09"
        iyz="-3.05855970793227E-10"
        izz="1.21769576262603E-09" />
    </inertial>
    <visual>
      <origin
        xyz="0 0 0"
        rpy="0 0 0" />
      <geometry>
        <mesh
          filename="package://hexaurdf10/meshes/tip3.STL" />
      </geometry>
      <material
        name="">
        <color
          rgba="0.792156862745098 0.819607843137255 0.933333333333333 1" />
      </material>
    </visual>
    <collision>
      <origin
        xyz="0 0 0"
        rpy="0 0 0" />
      <geometry>
        <mesh
          filename="package://hexaurdf10/meshes/tip3.STL" />
      </geometry>
    </collision>
  </link>
  <joint
    name="tip3_jt"
    type="fixed">
    <origin
      xyz="-0.0274588315162456 0.0242788522498839 -0.12040476058911"
      rpy="3.14159265358979 -1.5707963267949 0" />
    <parent
      link="tibia3" />
    <child
      link="tip3" />
    <axis
      xyz="0 0 0" />
    <limit
      effort="100"
      velocity="100" />
  </joint>
  <link
    name="coxa4">
    <inertial>
      <origin
        xyz="0.0184026875519722 -0.051195357644339 0.0282453400903533"
        rpy="0 0 0" />
      <mass
        value="0.115130487166804" />
      <inertia
        ixx="8.25624383588023E-05"
        ixy="1.18811126402559E-05"
        ixz="5.87909612155559E-08"
        iyy="4.25793913743434E-05"
        iyz="-1.8552050946634E-07"
        izz="7.59549000907778E-05" />
    </inertial>
    <visual>
      <origin
        xyz="0 0 0"
        rpy="0 0 0" />
      <geometry>
        <mesh
          filename="package://hexaurdf10/meshes/coxa4.STL" />
      </geometry>
      <material
        name="">
        <color
          rgba="0.792156862745098 0.819607843137255 0.933333333333333 1" />
      </material>
    </visual>
    <collision>
      <origin
        xyz="0 0 0"
        rpy="0 0 0" />
      <geometry>
        <mesh
          filename="package://hexaurdf10/meshes/coxa4.STL" />
      </geometry>
    </collision>
  </link>
  <joint
    name="coxajt4"
    type="revolute">
    <origin
      xyz="0.0870789894421607 -0.0473341409897536 -0.05093"
      rpy="0 0 0" />
    <parent
      link="base_link" />
    <child
      link="coxa4" />
    <axis
      xyz="0 0 -1" />
    <limit
      lower="-1.57"
      upper="1.57"
      effort="100"
      velocity="100" />
  </joint>
  <link
    name="femur4">
    <inertial>
      <origin
        xyz="-0.015725862641403 -0.0525267254797426 0.0258410063023246"
        rpy="0 0 0" />
      <mass
        value="0.0660859502202923" />
      <inertia
        ixx="5.28291550011744E-05"
        ixy="9.76091669185917E-07"
        ixz="-5.86007022599419E-06"
        iyy="4.9931894818005E-05"
        iyz="1.91840220420396E-05"
        izz="7.37056494379399E-05" />
    </inertial>
    <visual>
      <origin
        xyz="0 0 0"
        rpy="0 0 0" />
      <geometry>
        <mesh
          filename="package://hexaurdf10/meshes/femur4.STL" />
      </geometry>
      <material
        name="">
        <color
          rgba="0.792156862745098 0.819607843137255 0.933333333333333 1" />
      </material>
    </visual>
    <collision>
      <origin
        xyz="0 0 0"
        rpy="0 0 0" />
      <geometry>
        <mesh
          filename="package://hexaurdf10/meshes/femur4.STL" />
      </geometry>
    </collision>
  </link>
  <joint
    name="femurjt4"
    type="revolute">
    <origin
      xyz="0.0577315713668131 -0.065698102526794 0.0282"
      rpy="0 0 0" />
    <parent
      link="coxa4" />
    <child
      link="femur4" />
    <axis
      xyz="0.956375489427927 0.292140245809256 0" />
    <limit
      lower="-1.57"
      upper="1.57"
      effort="100"
      velocity="100" />
  </joint>
  <link
    name="tibia4">
    <inertial>
      <origin
        xyz="-0.0294274762289797 -0.0100598567813739 -0.0241284533134065"
        rpy="0 0 0" />
      <mass
        value="0.0831637325814451" />
      <inertia
        ixx="7.27246350617367E-05"
        ixy="-9.39619075551058E-07"
        ixz="1.99497186394999E-06"
        iyy="7.57139076346755E-05"
        iyz="-2.29705146782159E-06"
        izz="1.46527148890403E-05" />
    </inertial>
    <visual>
      <origin
        xyz="0 0 0"
        rpy="0 0 0" />
      <geometry>
        <mesh
          filename="package://hexaurdf10/meshes/tibia4.STL" />
      </geometry>
      <material
        name="">
        <color
          rgba="0.792156862745098 0.819607843137255 0.933333333333333 1" />
      </material>
    </visual>
    <collision>
      <origin
        xyz="0 0 0"
        rpy="0 0 0" />
      <geometry>
        <mesh
          filename="package://hexaurdf10/meshes/tibia4.STL" />
      </geometry>
    </collision>
  </link>
  <joint
    name="tibiajt4"
    type="revolute">
    <origin
      xyz="0.0225227920570593 -0.0822900871129893 0.0482836970507796"
      rpy="0 0 0" />
    <parent
      link="femur4" />
    <child
      link="tibia4" />
    <axis
      xyz="0.956375489427925 0.292140245809264 0" />
    <limit
      lower="-1.57"
      upper="1.57"
      effort="100"
      velocity="100" />
  </joint>
  <link
    name="tip4">
    <inertial>
      <origin
        xyz="-1.34483772956662E-05 4.40257670850236E-05 0.00101767568156874"
        rpy="0 0 0" />
      <mass
        value="0.000239235376940891" />
      <inertia
        ixx="1.21034606196609E-09"
        ixy="-2.93957096001634E-10"
        ixz="-8.05449062996898E-12"
        iyy="2.08287543495912E-09"
        iyz="2.63678747753188E-11"
        izz="2.78092765609382E-09" />
    </inertial>
    <visual>
      <origin
        xyz="0 0 0"
        rpy="0 0 0" />
      <geometry>
        <mesh
          filename="package://hexaurdf10/meshes/tip4.STL" />
      </geometry>
      <material
        name="">
        <color
          rgba="0.792156862745098 0.819607843137255 0.933333333333333 1" />
      </material>
    </visual>
    <collision>
      <origin
        xyz="0 0 0"
        rpy="0 0 0" />
      <geometry>
        <mesh
          filename="package://hexaurdf10/meshes/tip4.STL" />
      </geometry>
    </collision>
  </link>
  <joint
    name="tip4_jt"
    type="fixed">
    <origin
      xyz="-0.0304883031090567 -0.014930274944373 -0.121195324707457"
      rpy="0 0 0" />
    <parent
      link="tibia4" />
    <child
      link="tip4" />
    <axis
      xyz="0 0 0" />
  </joint>
  <link
    name="coxa5">
    <inertial>
      <origin
        xyz="0.00410518430927102 -0.0542473170200753 0.0282453387557866"
        rpy="0 0 0" />
      <mass
        value="0.11513051040574" />
      <inertia
        ixx="8.58264162082266E-05"
        ixy="-6.67351034550118E-08"
        ixz="7.25926080373979E-09"
        iyy="3.93154403087322E-05"
        iyz="-1.94481717827952E-07"
        izz="7.5954918900741E-05" />
    </inertial>
    <visual>
      <origin
        xyz="0 0 0"
        rpy="0 0 0" />
      <geometry>
        <mesh
          filename="package://hexaurdf10/meshes/coxa5.STL" />
      </geometry>
      <material
        name="">
        <color
          rgba="0.792156862745098 0.819607843137255 0.933333333333333 1" />
      </material>
    </visual>
    <collision>
      <origin
        xyz="0 0 0"
        rpy="0 0 0" />
      <geometry>
        <mesh
          filename="package://hexaurdf10/meshes/coxa5.STL" />
      </geometry>
    </collision>
  </link>
  <joint
    name="coxajt5"
    type="revolute">
    <origin
      xyz="-0.000209588055731805 -0.041977770408604 -0.05093"
      rpy="0 0 0" />
    <parent
      link="base_link" />
    <child
      link="coxa5" />
    <axis
      xyz="0 0 -1" />
    <limit
      lower="-1.57"
      upper="1.57"
      effort="100"
      velocity="100" />
  </joint>
  <link
    name="femur5">
    <inertial>
      <origin
        xyz="-0.0291455773014262 -0.0464423839953297 0.0258410061827461"
        rpy="0 0 0" />
      <mass
        value="0.0660859498433511" />
      <inertia
        ixx="5.31247863587691E-05"
        ixy="9.39931548988782E-08"
        ixz="-5.39886330744815E-07"
        iyy="4.96362625916426E-05"
        iyz="2.00518239660983E-05"
        izz="7.37056485399176E-05" />
    </inertial>
    <visual>
      <origin
        xyz="0 0 0"
        rpy="0 0 0" />
      <geometry>
        <mesh
          filename="package://hexaurdf10/meshes/femur5.STL" />
      </geometry>
      <material
        name="">
        <color
          rgba="0.792156862745098 0.819607843137255 0.933333333333333 1" />
      </material>
    </visual>
    <collision>
      <origin
        xyz="0 0 0"
        rpy="0 0 0" />
      <geometry>
        <mesh
          filename="package://hexaurdf10/meshes/femur5.STL" />
      </geometry>
    </collision>
  </link>
  <joint
    name="femurjt5"
    type="revolute">
    <origin
      xyz="0.0381519901013576 -0.0786994323957198 0.0282000000000001"
      rpy="0 0 0" />
    <parent
      link="coxa5" />
    <child
      link="femur5" />
    <axis
      xyz="0.99577013165006 -0.0918795130245163 0" />
    <limit
      lower="-1.57"
      upper="1.57"
      effort="100"
      velocity="100" />
  </joint>
  <link
    name="tibia5">
    <inertial>
      <origin
        xyz="-0.0310437838343144 -0.00186025755413441 -0.0241284529459698"
        rpy="0 0 0" />
      <mass
        value="0.0831637330024272" />
      <inertia
        ixx="7.24542516836029E-05"
        ixy="-3.90754073055744E-08"
        ixz="1.31124612349259E-06"
        iyy="7.59842909559781E-05"
        iyz="-2.74535773452344E-06"
        izz="1.46527148511911E-05" />
    </inertial>
    <visual>
      <origin
        xyz="0 0 0"
        rpy="0 0 0" />
      <geometry>
        <mesh
          filename="package://hexaurdf10/meshes/tibia5.STL" />
      </geometry>
      <material
        name="">
        <color
          rgba="0.792156862745098 0.819607843137255 0.933333333333333 1" />
      </material>
    </visual>
    <collision>
      <origin
        xyz="0 0 0"
        rpy="0 0 0" />
      <geometry>
        <mesh
          filename="package://hexaurdf10/meshes/tibia5.STL" />
      </geometry>
    </collision>
  </link>
  <joint
    name="tibiajt5"
    type="revolute">
    <origin
      xyz="-0.000203810616336522 -0.0853164290177546 0.0482836970507797"
      rpy="0 0 0" />
    <parent
      link="femur5" />
    <child
      link="tibia5" />
    <axis
      xyz="0.99577013165006 -0.0918795130245162 0" />
    <limit
      lower="-1.57"
      upper="1.57"
      effort="100"
      velocity="100" />
  </joint>
  <link
    name="tip5">
    <inertial>
      <origin
        xyz="-1.23898912395004E-06 4.60173002822251E-05 0.00101767568156877"
        rpy="0 0 0" />
      <mass
        value="0.000239235376940891" />
      <inertia
        ixx="1.12131430106366E-09"
        ixy="-2.83071249629712E-11"
        ixz="-7.42054306639292E-13"
        iyy="2.17190719586154E-09"
        iyz="2.75606421347752E-11"
        izz="2.78092765609381E-09" />
    </inertial>
    <visual>
      <origin
        xyz="0 0 0"
        rpy="0 0 0" />
      <geometry>
        <mesh
          filename="package://hexaurdf10/meshes/tip5.STL" />
      </geometry>
      <material
        name="">
        <color
          rgba="0.792156862745098 0.819607843137255 0.933333333333333 1" />
      </material>
    </visual>
    <collision>
      <origin
        xyz="0 0 0"
        rpy="0 0 0" />
      <geometry>
        <mesh
          filename="package://hexaurdf10/meshes/tip5.STL" />
      </geometry>
    </collision>
  </link>
  <joint
    name="tip5_jt"
    type="fixed">
    <origin
      xyz="-0.0333632688956824 -0.00627232213607404 -0.121195324707457"
      rpy="0 0 0" />
    <parent
      link="tibia5" />
    <child
      link="tip5" />
    <axis
      xyz="0 0 0" />
  </joint>
  <link
    name="coxa6">
    <inertial>
      <origin
        xyz="-0.0105561368542174 -0.0533684505149676 0.028245339183021"
        rpy="0 0 0" />
      <mass
        value="0.115130490364098" />
      <inertia
        ixx="8.24635969125576E-05"
        ixy="-1.20458859339554E-05"
        ixz="-4.50328049686864E-08"
        iyy="4.26782432416758E-05"
        iyz="-1.89334946137937E-07"
        izz="7.59549015442438E-05" />
    </inertial>
    <visual>
      <origin
        xyz="0 0 0"
        rpy="0 0 0" />
      <geometry>
        <mesh
          filename="package://hexaurdf10/meshes/coxa6.STL" />
      </geometry>
      <material
        name="">
        <color
          rgba="0.792156862745098 0.819607843137255 0.933333333333333 1" />
      </material>
    </visual>
    <collision>
      <origin
        xyz="0 0 0"
        rpy="0 0 0" />
      <geometry>
        <mesh
          filename="package://hexaurdf10/meshes/coxa6.STL" />
      </geometry>
    </collision>
  </link>
  <joint
    name="coxajt6"
    type="revolute">
    <origin
      xyz="-0.0874337290454854 -0.0471785774978922 -0.05093"
      rpy="0 0 0" />
    <parent
      link="base_link" />
    <child
      link="coxa6" />
    <axis
      xyz="0 0 -1" />
    <limit
      lower="-1.57"
      upper="1.57"
      effort="100"
      velocity="100" />
  </joint>
  <link
    name="femur6">
    <inertial>
      <origin
        xyz="-0.0405071770934144 -0.0369530550570344 0.0258410062748393"
        rpy="0 0 0" />
      <mass
        value="0.0660859501573358" />
      <inertia
        ixx="5.29235976142282E-05"
        ixy="-8.18663856820692E-07"
        ixz="4.84385613705719E-06"
        iyy="4.98374520649631E-05"
        iyz="1.9465461262276E-05"
        izz="7.37056492773609E-05" />
    </inertial>
    <visual>
      <origin
        xyz="0 0 0"
        rpy="0 0 0" />
      <geometry>
        <mesh
          filename="package://hexaurdf10/meshes/femur6.STL" />
      </geometry>
      <material
        name="">
        <color
          rgba="0.792156862745098 0.819607843137255 0.933333333333333 1" />
      </material>
    </visual>
    <collision>
      <origin
        xyz="0 0 0"
        rpy="0 0 0" />
      <geometry>
        <mesh
          filename="package://hexaurdf10/meshes/femur6.STL" />
      </geometry>
    </collision>
  </link>
  <joint
    name="femurjt6"
    type="revolute">
    <origin
      xyz="0.0157086456858173 -0.0860372794712854 0.0282000000000001"
      rpy="0 0 0" />
    <parent
      link="coxa6" />
    <child
      link="femur6" />
    <axis
      xyz="0.990436681141514 -0.137968042130713 0" />
    <limit
      lower="-1.57"
      upper="1.57"
      effort="100"
      velocity="100" />
  </joint>
  <link
    name="tibia6">
    <inertial>
      <origin
        xyz="-0.0304100328765285 0.00651206661555905 -0.0241284534107476"
        rpy="0 0 0" />
      <mass
        value="0.0831637299024112" />
      <inertia
        ixx="7.26867226472065E-05"
        ixy="8.76422795977241E-07"
        ixz="5.29046637943043E-07"
        iyy="7.57518185875592E-05"
        iyz="-2.99607478919625E-06"
        izz="1.46527142528795E-05" />
    </inertial>
    <visual>
      <origin
        xyz="0 0 0"
        rpy="0 0 0" />
      <geometry>
        <mesh
          filename="package://hexaurdf10/meshes/tibia6.STL" />
      </geometry>
      <material
        name="">
        <color
          rgba="0.792156862745098 0.819607843137255 0.933333333333333 1" />
      </material>
    </visual>
    <collision>
      <origin
        xyz="0 0 0"
        rpy="0 0 0" />
      <geometry>
        <mesh
          filename="package://hexaurdf10/meshes/tibia6.STL" />
      </geometry>
    </collision>
  </link>
  <joint
    name="tibiajt6"
    type="revolute">
    <origin
      xyz="-0.0230193932677872 -0.0821525540241559 0.0482836970507797"
      rpy="0 0 0" />
    <parent
      link="femur6" />
    <child
      link="tibia6" />
    <axis
      xyz="0.990436681141515 -0.137968042130712 0" />
    <limit
      lower="-1.57"
      upper="1.57"
      effort="100"
      velocity="100" />
  </joint>
  <link
    name="tip6">
    <inertial>
      <origin
        xyz="1.11162605727633E-05 4.46716439164024E-05 0.00101767568156877"
        rpy="0 0 0" />
      <mass
        value="0.000239235376940892" />
      <inertia
        ixx="1.18190356101911E-09"
        ixy="2.46545900213277E-10"
        ixz="6.65774127650596E-12"
        iyy="2.11131793590611E-09"
        iyz="2.67547027748436E-11"
        izz="2.78092765609382E-09" />
    </inertial>
    <visual>
      <origin
        xyz="0 0 0"
        rpy="0 0 0" />
      <geometry>
        <mesh
          filename="package://hexaurdf10/meshes/tip6.STL" />
      </geometry>
      <material
        name="">
        <color
          rgba="0.792156862745098 0.819607843137255 0.933333333333333 1" />
      </material>
    </visual>
    <collision>
      <origin
        xyz="0 0 0"
        rpy="0 0 0" />
      <geometry>
        <mesh
          filename="package://hexaurdf10/meshes/tip6.STL" />
      </geometry>
    </collision>
  </link>
  <joint
    name="tip6_jt"
    type="fixed">
    <origin
      xyz="-0.0338252558164659 0.00288128536159279 -0.121195324707457"
      rpy="0 0 0" />
    <parent
      link="tibia6" />
    <child
      link="tip6" />
    <axis
      xyz="0 0 0" />
  </joint>
  <link
    name="imu_link">
    <inertial>
      <origin
        xyz="0 0 -0.0005"
        rpy="0 0 0" />
      <mass
        value="0.000375" />
      <inertia
        ixx="7.0625E-09"
        ixy="-3.59111970552275E-24"
        ixz="2.68192909831876E-26"
        iyy="1.95625E-08"
        iyz="-2.88153880920263E-26"
        izz="2.65625E-08" />
    </inertial>
    <visual>
      <origin
        xyz="0 0 0"
        rpy="0 0 0" />
      <geometry>
        <mesh
          filename="package://hexaurdf10/meshes/imu_link.STL" />
      </geometry>
      <material
        name="">
        <color
          rgba="0.752941176470588 0.752941176470588 0.752941176470588 1" />
      </material>
    </visual>
    <collision>
      <origin
        xyz="0 0 0"
        rpy="0 0 0" />
      <geometry>
        <mesh
          filename="package://hexaurdf10/meshes/imu_link.STL" />
      </geometry>
    </collision>
  </link>
  <joint
    name="imu_jt"
    type="fixed">
    <origin
      xyz="-9.9588E-05 0 0.001"
      rpy="0 0 0" />
    <parent
      link="base_link" />
    <child
      link="imu_link" />
    <axis
      xyz="0 0 0" />
  </joint>
  <link
    name="camera_link">
    <inertial>
      <origin
        xyz="-0.00114302589325548 -0.000416882271136926 -0.00295566016403626"
        rpy="0 0 0" />
      <mass
        value="0.0248866659018299" />
      <inertia
        ixx="1.70926741034642E-05"
        ixy="-2.3838492933783E-10"
        ixz="2.8776091691926E-07"
        iyy="3.42775100270887E-06"
        iyz="-6.17185832086283E-07"
        izz="1.92498237281233E-05" />
    </inertial>
    <visual>
      <origin
        xyz="0 0 0"
        rpy="0 0 0" />
      <geometry>
        <mesh
          filename="package://hexaurdf10/meshes/camera_link.STL" />
      </geometry>
      <material
        name="">
        <color
          rgba="0.752941176470588 0.752941176470588 0.752941176470588 1" />
      </material>
    </visual>
    <collision>
      <origin
        xyz="0 0 0"
        rpy="0 0 0" />
      <geometry>
        <mesh
          filename="package://hexaurdf10/meshes/camera_link.STL" />
      </geometry>
    </collision>
  </link>
  <joint
    name="camera_jt"
    type="fixed">
    <origin
      xyz="-0.11366 0.00028085 0.073621"
      rpy="3.1285 -1.0471 3.1416" />
    <parent
      link="base_link" />
    <child
      link="camera_link" />
    <axis
      xyz="0 0 0" />
  </joint>
</robot>